Workbook

Sheet DATA
A1: DATA MASTER PENUGASAN — MPP BPKP
A2: Kuning = isian pengguna; Abu-abu = formula otomatis. Contoh isian nyata tersedia langsung pada Kolom D.
A3: TIM PENGAWASAN | B3: Nama Pegawai | C3: NIP (Teks 18 Digit) | D3: Petunjuk & Contoh Isian
A4: Wakil Penanggung Jawab | D4: Ketik nama dan NIP 18 digit angka. Wajib diisi.
A5: Pengendali Teknis | D5: Ketik nama dan NIP 18 digit angka. Wajib diisi.
A6: Ketua Tim | D6: Ketik nama dan NIP 18 digit angka. Wajib diisi.
A7: Anggota Tim | D7: Anggota Tim 1: Ketik nama dan NIP (baris tidak digunakan cukup dikosongkan).
A8: Anggota Tim | D8: Anggota Tim 2: Ketik nama dan NIP (baris tidak digunakan cukup dikosongkan).
A9: Anggota Tim | D9: Anggota Tim 3: Ketik nama dan NIP (baris tidak digunakan cukup dikosongkan).
A10: Anggota Tim | D10: Anggota Tim 4: Ketik nama dan NIP (baris tidak digunakan cukup dikosongkan).
A11: Anggota Tim | D11: Anggota Tim 5: Ketik nama dan NIP (baris tidak digunakan cukup dikosongkan).
A12: Anggota Tim | D12: Anggota Tim 6: Ketik nama dan NIP (baris tidak digunakan cukup dikosongkan).
A13: Anggota Tim | D13: Anggota Tim 7: Ketik nama dan NIP (baris tidak digunakan cukup dikosongkan).
A14: Anggota Tim | D14: Anggota Tim 8: Ketik nama dan NIP (baris tidak digunakan cukup dikosongkan).
A15: Anggota Tim | D15: Anggota Tim 9: Ketik nama dan NIP (baris tidak digunakan cukup dikosongkan).
... A27: Kepala Perwakilan | D27: Ketik nama dan NIP Kepala Perwakilan penandatangan Surat Tugas.
A28: DETAIL PENUGASAN
A29: Bidang | D29: Pilihan bidang: Umum, IPP, APD, AN, Investigasi, P3A (Gunakan dropdown). | E29: BIDANG
A30: Nama lengkap penugasan / judul folder | D30: Contoh: Evaluasi atas Tata Kelola Program Ketahanan Pangan pada Pemerintah Kabupaten Nabire | E30: NAMA_PENUGASAN
A31: Sasaran pengawasan | D31: Contoh: Menilai efektivitas dan akuntabilitas penyaluran bantuan cadangan pangan pemerintah daerah | E31: SASARAN_PENGAWASAN
A32: Nomor kartu penugasan | D32: Contoh: KP-01/PW36/2/2026 (Opsional, boleh kosong saat konsep) | E32: NOMOR_KP
A33: Nama objek/entitas pengawasan | D33: Contoh: Dinas Ketahanan Pangan Kabupaten Nabire | E33: DAFTAR_OBJEK_PENGAWASAN
A34: Tahun anggaran/periode objek | D34: Contoh: Triwulan III Tahun 2026 (atau Tahun Anggaran 2026) | E34: PERIODE_OBJEK
A35: Nomor rencana pengawasan | D35: Contoh: R-01/PW36/2/2026 (Opsional / sesuai kondisi) | E35: NOMOR_RENCANA
A36: Tingkat risiko | B36: Sedang | D36: Pilihan tingkat risiko: Rendah, Sedang, Tinggi (Gunakan dropdown, default: Sedang) | E36: TINGKAT_RISIKO
A37: Alamat dan telepon objek | D37: Contoh: Jl. Merdeka No. 1, Nabire, Papua Tengah (Telp. 0984-21001) | E37: ALAMAT_OBJEK
A38: JADWAL PENUGASAN
A39: Tanggal konsep surat tugas | D39: Contoh: 02/11/2026 (Format tanggal Surat Tugas) | E39: TANGGAL_ST
A40: Tanggal pengesahan perencanaan | B40: =IF(B39="","",B39) | D40: Otomatis: sama dengan Tanggal Konsep ST | E40: TANGGAL_PENGESAHAN
A41: Hari kerja kalender fase persiapan | D41: Contoh: 1 (Jumlah hari kerja kalender fase persiapan) | E41: HARI_PERSIAPAN
A42: Hari kerja kalender fase pelaksanaan | D42: Contoh: 3 (Jumlah hari kerja kalender fase pelaksanaan) | E42: HARI_PELAKSANAAN
A43: Hari kerja kalender fase penyelesaian | D43: Contoh: 1 (Jumlah hari kerja kalender fase penyelesaian) | E43: HARI_PENYELESAIAN
A44: Mulai persiapan | B44: =IF(B39="","",WORKDAY(B39,2)) | D44: Otomatis: dihitung 2 hari kerja setelah tanggal ST | E44: PERS_MULAI
A45: Selesai persiapan | B45: =IF(OR(B44="",B41=""),"",WORKDAY(B44,B41-1)) | D45: Otomatis: rentang hari persiapan | E45: PERS_SELESAI
A46: Mulai pelaksanaan | B46: =IF(B45="","",WORKDAY(B45,1)) | D46: Otomatis: awal pelaksanaan | E46: LAKS_MULAI
A47: Selesai pelaksanaan | B47: =IF(OR(B46="",B42=""),"",WORKDAY(B46,B42-1)) | D47: Otomatis: akhir pelaksanaan (Sabtu dan Minggu dilewati otomatis) | E47: LAKS_SELESAI
A48: Mulai penyelesaian | B48: =IF(B47="","",WORKDAY(B47,1)) | D48: Otomatis: awal penyelesaian | E48: SELESAI_MULAI
A49: Selesai penyelesaian | B49: =IF(OR(B48="",B43=""),"",WORKDAY(B48,B43-1)) | D49: Otomatis: akhir penyelesaian | E49: SELESAI_AKHIR
A50: Direncanakan selesai penugasan | B50: =IF(B49="","",B49) | D50: Otomatis: direncanakan selesai penugasan ST | E50: TANGGAL_SELESAI
A51: Rencana penerbitan laporan (RPL) | B51: =IF(B50="","",B50) | D51: Otomatis: Rencana Penerbitan Laporan (RPL) | E51: RPL
...

Sheet IHP
A1: IHP
A2: Ketik butir Insilwas per baris (boleh diawali ID seperti IHP-01, nomor 1., atau langsung uraian; skrip otomatis mengekstrak ID).
A4: Informasi Hasil Pengawasan (Insilwas)

Sheet TEMBUSAN
A1: TEMBUSAN
A2: Isi baris mulai 5; baris kosong tidak diproses. Tambahkan baris bila diperlukan.
A4: Jabatan/instansi penerima tembusan

Sheet JAM_TIM
A1: ALOKASI JAM TIAP PERSONEL
A2: Awal: partisipasi penuh × hari fase × jam/hari. Tinjau PM/PT/anggota dan ubah jam fase di E:G bila berbeda. Anggaran, bukan realisasi.
A4: No. | B4: Peran | C4: Nama | D4: NIP | E4: Persiapan (jam) | F4: Pelaksanaan (jam) | G4: Penyelesaian (jam) | H4: Total (jam)
A5: 1 | B5: Wakil Penanggung Jawab | C5: =IF(DATA!B4="","",DATA!B4) | D5: =IF(DATA!B4="","",DATA!C4&"") | E5: =IF(C5="","",DATA!$B$41*DATA!$B$53) | F5: =IF(C5="","",DATA!$B$42*DATA!$B$53) | G5: =IF(C5="","",DATA!$B$43*DATA!$B$53) | H5: =IF(C5="","",SUM(E5:G5))
A6: 2 | B6: Pengendali Teknis | C6: =IF(DATA!B5="","",DATA!B5) | D6: =IF(DATA!B5="","",DATA!C5&"") | E6: =IF(C6="","",DATA!$B$41*DATA!$B$53) | F6: =IF(C6="","",DATA!$B$42*DATA!$B$53) | G6: =IF(C6="","",DATA!$B$43*DATA!$B$53) | H6: =IF(C6="","",SUM(E6:G6))
A7: 3 | B7: Ketua Tim | C7: =IF(DATA!B6="","",DATA!B6) | D7: =IF(DATA!B6="","",DATA!C6&"") | E7: =IF(C7="","",DATA!$B$41*DATA!$B$53) | F7: =IF(C7="","",DATA!$B$42*DATA!$B$53) | G7: =IF(C7="","",DATA!$B$43*DATA!$B$53) | H7: =IF(C7="","",SUM(E7:G7))
A8: 4 | B8: Anggota Tim | C8: =IF(DATA!B7="","",DATA!B7) | D8: =IF(DATA!B7="","",DATA!C7&"") | E8: =IF(C8="","",DATA!$B$41*DATA!$B$53) | F8: =IF(C8="","",DATA!$B$42*DATA!$B$53) | G8: =IF(C8="","",DATA!$B$43*DATA!$B$53) | H8: =IF(C8="","",SUM(E8:G8))
A9: 5 | B9: Anggota Tim | C9: =IF(DATA!B8="","",DATA!B8) | D9: =IF(DATA!B8="","",DATA!C8&"") | E9: =IF(C9="","",DATA!$B$41*DATA!$B$53) | F9: =IF(C9="","",DATA!$B$42*DATA!$B$53) | G9: =IF(C9="","",DATA!$B$43*DATA!$B$53) | H9: =IF(C9="","",SUM(E9:G9))
A10: 6 | B10: Anggota Tim | C10: =IF(DATA!B9="","",DATA!B9) | D10: =IF(DATA!B9="","",DATA!C9&"") | E10: =IF(C10="","",DATA!$B$41*DATA!$B$53) | F10: =IF(C10="","",DATA!$B$42*DATA!$B$53) | G10: =IF(C10="","",DATA!$B$43*DATA!$B$53) | H10: =IF(C10="","",SUM(E10:G10))
A11: 7 | B11: Anggota Tim | C11: =IF(DATA!B10="","",DATA!B10) | D11: =IF(DATA!B10="","",DATA!C10&"") | E11: =IF(C11="","",DATA!$B$41*DATA!$B$53) | F11: =IF(C11="","",DATA!$B$42*DATA!$B$53) | G11: =IF(C11="","",DATA!$B$43*DATA!$B$53) | H11: =IF(C11="","",SUM(E11:G11))
A12: 8 | B12: Anggota Tim | C12: =IF(DATA!B11="","",DATA!B11) | D12: =IF(DATA!B11="","",DATA!C11&"") | E12: =IF(C12="","",DATA!$B$41*DATA!$B$53) | F12: =IF(C12="","",DATA!$B$42*DATA!$B$53) | G12: =IF(C12="","",DATA!$B$43*DATA!$B$53) | H12: =IF(C12="","",SUM(E12:G12))
A13: 9 | B13: Anggota Tim | C13: =IF(DATA!B12="","",DATA!B12) | D13: =IF(DATA!B12="","",DATA!C12&"") | E13: =IF(C13="","",DATA!$B$41*DATA!$B$53) | F13: =IF(C13="","",DATA!$B$42*DATA!$B$53) | G13: =IF(C13="","",DATA!$B$43*DATA!$B$53) | H13: =IF(C13="","",SUM(E13:G13))
A14: 10 | B14: Anggota Tim | C14: =IF(DATA!B13="","",DATA!B13) | D14: =IF(DATA!B13="","",DATA!C13&"") | E14: =IF(C14="","",DATA!$B$41*DATA!$B$53) | F14: =IF(C14="","",DATA!$B$42*DATA!$B$53) | G14: =IF(C14="","",DATA!$B$43*DATA!$B$53) | H14: =IF(C14="","",SUM(E14:G14))
A15: 11 | B15: Anggota Tim | C15: =IF(DATA!B14="","",DATA!B14) | D15: =IF(DATA!B14="","",DATA!C14&"") | E15: =IF(C15="","",DATA!$B$41*DATA!$B$53) | F15: =IF(C15="","",DATA!$B$42*DATA!$B$53) | G15: =IF(C15="","",DATA!$B$43*DATA!$B$53) | H15: =IF(C15="","",SUM(E15:G15))
A16: 12 | B16: Anggota Tim | C16: =IF(DATA!B15="","",DATA!B15) | D16: =IF(DATA!B15="","",DATA!C15&"") | E16: =IF(C16="","",DATA!$B$41*DATA!$B$53) | F16: =IF(C16="","",DATA!$B$42*DATA!$B$53) | G16: =IF(C16="","",DATA!$B$43*DATA!$B$53) | H16: =IF(C16="","",SUM(E16:G16))
... A27: 23 | B27: Anggota Tim | C27: =IF(DATA!B26="","",DATA!B26) | D27: =IF(DATA!B26="","",DATA!C26&"") | E27: =IF(C27="","",DATA!$B$41*DATA!$B$53) | F27: =IF(C27="","",DATA!$B$42*DATA!$B$53) | G27: =IF(C27="","",DATA!$B$43*DATA!$B$53) | H27: =IF(C27="","",SUM(E27:G27))
